Workbook

Sheet relevamiento_educacion
A1: cueanexo | B1: NIVEL | C1: ESCUELA | D1: NOMBRE | E1: DIRECCIÓN | F1: X | G1: Y | H1: MAIL/CONTACTO | I1: GESTIÓN | J1: TURNO | K1: SITUACIÓN DE MAPEO | L1: CUPOS SAE 2024 INICIAL | M1: CUPOS SAE 2024 FINAL | N1: CUPOS SAE 2025 INICIAL
A2: 0117SC0001 | B2: ESPECIAL | C2: CEC 801 | E2: Paso y Lorca s/n | F2: -58.5415 | G2: -34.6237 | H2: cec801tresdefebrero@abc.gob.ar | I2: PBA | J2: M-T | K2: Validado | L2: =VLOOKUP(C2,'Hoja 5'!$A$2:$D$135,2,FALSE()) -> 120 | M2: =VLOOKUP(C2,'Hoja 5'!$A$2:$D$135,3,FALSE()) -> 120 | N2: =VLOOKUP(C2,'Hoja 5'!$A$2:$D$135,4,FALSE()) -> 120
A3: 0117FC0123 | B3: ESPECIAL | C3: CEF 123 | E3: Lisandro de la Torre 3855 | F3: -58.5582 | G3: -34.6187 | H3: cef123tresdefebrero@abc.gob.ar | I3: PBA | J3: M-T-V | K3: Validado | L3: =VLOOKUP(C3,'Hoja 5'!$A$2:$D$135,2,FALSE()) -> 90 | M3: =VLOOKUP(C3,'Hoja 5'!$A$2:$D$135,3,FALSE()) -> 130 | N3: =VLOOKUP(C3,'Hoja 5'!$A$2:$D$135,4,FALSE()) -> 130
A4: 0117EE0501 | B4: ESPECIAL | C4: EE 501 | E4: Labardén y Bolivia | F4: -58.5563 | G4: -34.6173 | H4: especial501tresdefebrero@abc.gob.ar | I4: PBA | J4: M-T | K4: Validado | L4: =VLOOKUP(C4,'Hoja 5'!$A$2:$D$135,2,FALSE()) -> 150 | M4: =VLOOKUP(C4,'Hoja 5'!$A$2:$D$135,3,FALSE()) -> 161 | N4: =VLOOKUP(C4,'Hoja 5'!$A$2:$D$135,4,FALSE()) -> 165
A5: 0117EE0502 | B5: ESPECIAL | C5: EE 502 | E5: Sgto.Palma 1333 | F5: -58.5827 | G5: -34.5849 | H5: especial502tresdefebrero@abc.gob.ar | I5: PBA | J5: M-T | K5: Validado | L5: =VLOOKUP(C5,'Hoja 5'!$A$2:$D$135,2,FALSE()) -> 77 | M5: =VLOOKUP(C5,'Hoja 5'!$A$2:$D$135,3,FALSE()) -> 90 | N5: =VLOOKUP(C5,'Hoja 5'!$A$2:$D$135,4,FALSE()) -> 90
A6: 0117EE0503 | B6: ESPECIAL | C6: EE 503 | E6: Sarmiento 4460 | F6: -58.5668 | G6: -34.6252 | H6: especial503tresdefebrero@abc.gob.ar | I6: PBA | J6: M-T | K6: Validado | L6: =VLOOKUP(C6,'Hoja 5'!$A$2:$D$135,2,FALSE()) -> 120 | M6: =VLOOKUP(C6,'Hoja 5'!$A$2:$D$135,3,FALSE()) -> 163 | N6: =VLOOKUP(C6,'Hoja 5'!$A$2:$D$135,4,FALSE()) -> 163
A7: 0117PP0001 | B7: PRIMARIA | C7: EP 01 | E7: W. de Tata 4930 | F7: -58.5664 | G7: -34.6014 | H7: primaria1tresdefebrero@abc.gob.ar | I7: PBA | J7: M | K7: Validado | L7: =VLOOKUP(C7,'Hoja 5'!$A$2:$D$135,2,FALSE()) -> 80 | M7: =VLOOKUP(C7,'Hoja 5'!$A$2:$D$135,3,FALSE()) -> 78 | N7: =VLOOKUP(C7,'Hoja 5'!$A$2:$D$135,4,FALSE()) -> 88
A8: 0117PP0002 | B8: PRIMARIA | C8: EP 02 | E8: Urquiza 4417 | F8: -58.5574 | G8: -34.606 | H8: primaria2tresdefebrero@abc.gob.ar | I8: PBA | J8: T | K8: Validado | L8: =VLOOKUP(C8,'Hoja 5'!$A$2:$D$135,2,FALSE()) -> 110 | M8: =VLOOKUP(C8,'Hoja 5'!$A$2:$D$135,3,FALSE()) -> 116 | N8: =VLOOKUP(C8,'Hoja 5'!$A$2:$D$135,4,FALSE()) -> 100
A9: 0117PP0003 | B9: PRIMARIA | C9: EP 03 | E9: Garcia Lorca 2768 | F9: -58.5365 | G9: -34.6203 | H9: primaria3tresdefebrero@abc.gob.ar | I9: PBA | J9: J-C | K9: Validado | L9: =VLOOKUP(C9,'Hoja 5'!$A$2:$D$135,2,FALSE()) -> 272 | M9: =VLOOKUP(C9,'Hoja 5'!$A$2:$D$135,3,FALSE()) -> 270 | N9: =VLOOKUP(C9,'Hoja 5'!$A$2:$D$135,4,FALSE()) -> 270
A10: 0117PP0004 | B10: PRIMARIA | C10: EP 04 | E10: Puán 4851 | F10: -58.5654 | G10: -34.6148 | H10: primaria4tresdefebrero@abc.gob.ar | I10: PBA | J10: M-T | K10: Validado | L10: =VLOOKUP(C10,'Hoja 5'!$A$2:$D$135,2,FALSE()) -> 216 | M10: =VLOOKUP(C10,'Hoja 5'!$A$2:$D$135,3,FALSE()) -> 216 | N10: =VLOOKUP(C10,'Hoja 5'!$A$2:$D$135,4,FALSE()) -> 209
A11: 0117PP0005 | B11: PRIMARIA | C11: EP 05 | E11: Larralde 1521 | F11: -58.5679 | G11: -34.5957 | H11: primaria5tresdefebrero@abc.gob.ar | I11: PBA | J11: M-T | K11: Validado | L11: =VLOOKUP(C11,'Hoja 5'!$A$2:$D$135,2,FALSE()) -> 426 | M11: =VLOOKUP(C11,'Hoja 5'!$A$2:$D$135,3,FALSE()) -> 390 | N11: =VLOOKUP(C11,'Hoja 5'!$A$2:$D$135,4,FALSE()) -> 300
A12: 0117PP0006 | B12: PRIMARIA | C12: EP 06 | E12: Almafuerte 3390 | F12: -58.5443 | G12: -34.6036 | H12: primaria6tresdefebrero@abc.gob.ar | I12: PBA | J12: M | K12: Validado | L12: =VLOOKUP(C12,'Hoja 5'!$A$2:$D$135,2,FALSE()) -> 115 | M12: =VLOOKUP(C12,'Hoja 5'!$A$2:$D$135,3,FALSE()) -> 102 | N12: =VLOOKUP(C12,'Hoja 5'!$A$2:$D$135,4,FALSE()) -> 102
A13: 0117PP0007 | B13: PRIMARIA | C13: EP 07 | E13: Spandonari 3369 | F13: -58.5771 | G13: -34.6133 | H13: primaria7tresdefebrero@abc.gob.ar | I13: PBA | J13: M-T | K13: Validado | L13: =VLOOKUP(C13,'Hoja 5'!$A$2:$D$135,2,FALSE()) -> 278 | M13: =VLOOKUP(C13,'Hoja 5'!$A$2:$D$135,3,FALSE()) -> 268 | N13: =VLOOKUP(C13,'Hoja 5'!$A$2:$D$135,4,FALSE()) -> 252
... A135: 0117MT0003 | B135: SECUNDARIA | C135: TEC 3 | E135: Emancipador 10080 | F135: -58.6125 | G135: -34.5584 | H135: eest3tresdefebrero@abc.gob.ar | I135: PBA | J135: T-V | K135: Validado | L135: =VLOOKUP(C135,'Hoja 5'!$A$2:$D$135,2,FALSE()) -> 830 | M135: =VLOOKUP(C135,'Hoja 5'!$A$2:$D$135,3,FALSE()) -> 759 | N135: =VLOOKUP(C135,'Hoja 5'!$A$2:$D$135,4,FALSE()) -> 759
A136: 3117JI6374 | B136: JARDIN | C136: JM ALADINO | E136: Asuncion 2463 | F136: -58.5364 | G136: -34.6161 | H136: jardinmunicipalaladino@gmail.com | I136: MUNICIPAL | K136: Validado
A137: 3117JI1252 | B137: JARDIN | C137: JM ANTEOJITO | E137: Abdón Garcia 4592 | F137: -58.5538 | G137: -34.6328 | H137: anteojito1252@hotmail.com | I137: MUNICIPAL | K137: Validado
A138: 3117JI6373 | B138: JARDIN | C138: JM ARDILLITAS TRAVIESAS | E138: Guamini 5250 * | F138: -58.5727 | G138: -34.617 | H138: ardillitastraviesas63@gmail.com | I138: MUNICIPAL | K138: Validado
A139: 3117JI1784 | B139: JARDIN | C139: JM ARENALES | E139: Av. Militar 3371 * | F139: -58.545 | G139: -34.6225 | H139: jardinarenales@yahoo.com.ar | I139: MUNICIPAL | K139: Validado
A140: 3117JI1279 | B140: JARDIN | C140: JM BAMBI | E140: Dante 4580 | F140: -58.5596 | G140: -34.5979 | H140: paula_berazategui@yahoo.com.ar | I140: MUNICIPAL | K140: Validado
A141: 3117JI6372 | B141: JARDIN | C141: JM BICHITO DE LUZ | E141: Ramallo 5201 | F141: -58.5725 | G141: -34.6262 | H141: jardinmunicipalbichitodeluz@outlook.com | I141: MUNICIPAL | K141: Validado
A142: 3117JI1274 | B142: JARDIN | C142: JM CAMINITO | E142: Angel Pini 5238 | F142: -58.5725 | G142: -34.6191 | H142: amarellemg2@gmail.com | I142: MUNICIPAL | K142: Validado
A143: 3117JI1542 | B143: JARDIN | C143: JM CEBOLLITAS | E143: Padre Elizalde 102 | F143: -58.5425 | G143: -34.6386 | H143: jmcebollitas1542@gmail.com | I143: MUNICIPAL | K143: Validado
A144: 3117JI2087 | B144: JARDIN | C144: JM DESPERTAR | E144: Churruca 10126 | F144: -58.6176 | G144: -34.5621 | H144: jmdespertar@gmail.com | I144: MUNICIPAL | K144: Validado
A145: 3117JI1258 | B145: JARDIN | C145: JM DUMBO | E145: N.S.d.La Merced 3464 | F145: -58.547 | G145: -34.6143 | H145: jardinmunicipaldumbo@gmail.com | I145: MUNICIPAL | K145: Validado
A146: 3117JI2193 | B146: JARDIN | C146: JM EL GAUCHITO | E146: El Gaucho y Salguero (Salguero 660) | F146: -58.6124 | G146: -34.5552 | H146: elgauchito2193@gmail.com | I146: MUNICIPAL | K146: Validado
A147: 3117JI2748 | B147: JARDIN | C147: JM EL LIBERTADOR | E147: S.d.Est. y Emancipador (Stiago del estero 900) | F147: -58.612 | G147: -34.559 | H147: jmunicipalellibertador@gmail.com | I147: MUNICIPAL | K147: Validado
... A162: 3117JM6375 | B162: JARDIN | C162: JM TERNURITAS | E162: José Murias y Alberdi (Alberdi 4850) | F162: -58.5654 | G162: -34.6037 | H162: jternuritas@gmail.com | I162: MUNICIPAL | K162: Validado
B163: DISPOSITIVO | C163: UDI Mi Mamita | E163: El gaucho y Salguero | F163: -58.6129 | G163: -34.5552 | H163: equipotecnicomimamita@gmail.com | I163: MUNICIPAL | K163: Validado
B164: DISPOSITIVO | C164: UDI Mi Refugio | E164: Dardo Rocha y Besares | F164: -58.53981 | G164: -34.6193 | H164: udimirefugio@gmail.com | I164: MUNICIPAL | K164: Validado
B165: DISPOSITIVO | C165: UDI Mi Nueva Esperanza | E165: Cerro Olivares y Volcan San Jose | F165: -58.5597 | G165: -34.6159 | H165: udiminuevaesperanza3f@gmail.com | I165: MUNICIPAL | K165: Validado
B166: DISPOSITIVO | C166: EPI Mi Casita | E166: Gabino Ezeiza 10050 | F166: -58.6156 | G166: -34.56122 | H166: Coordinacionepis3f@gmail.com | I166: MUNICIPAL | K166: Validado
B167: DISPOSITIVO | C167: EPI Estrella de Belén | E167: Necochea y Richieri s/n | F167: -58.5376 | G167: -34.6218 | H167: Coordinacionepis3f@gmail.com | I167: MUNICIPAL | K167: Validado
B168: DISPOSITIVO | C168: EPI Caseritos | E168: Volcan san José 4550 | F168: -58.56015 | G168: -34.616 | H168: Coordinacionepis3f@gmail.com | I168: MUNICIPAL | K168: Validado
B169: DISPOSITIVO | C169: ENVIÓN Libertador | E169: miramar 815 | F169: -58.6178 | G169: -34.5525 | H169: envion.libertador@gmail.com | I169: MUNICIPAL | K169: Validado
B170: DISPOSITIVO | C170: ENVIÓN Ejercito | E170: marcelo t de alvear 3386 | F170: -58.5472 | G170: -34.6193 | H170: envionejercito@gmail.com | I170: MUNICIPAL | K170: Validado
B171: DISPOSITIVO | C171: ENVIÓN Evita | E171: labarden 4255 | F171: -58.5556 | G171: -34.61707 | H171: envionbarrioevita@gmail.com | I171: MUNICIPAL | K171: Validado
B172: DISPOSITIVO | C172: TALLER PROTEGIDO | E172: Betharram 1542 | F172: -58.588 | G172: -34.58346 | H172: miriveraparedes@gmail.com | I172: MUNICIPAL | K172: Validado
A173: 0117DE0701 | B173: ADULTOS | C173: EPA 701 | E173: Urquiza 4694 | F173: -58.5619 | G173: -34.606 | I173: PBA | K173: Validado
A174: 0117DE0702 | B174: ADULTOS | C174: EPA 702 | E174: Iguazú 10494 | F174: -58.6203 | G174: -34.5592 | I174: PBA | K174: Validado
A175: 0117DE0703 | B175: ADULTOS | C175: EPA 703 | E175: Necochea y Ricchieri | F175: -58.5375 | G175: -34.6236 | I175: PBA | K175: Validado
...
